Workbook

Sheet SWiSH Demand Forecast Sep-26
A1: Date | B1: Branch | C1: Recipe group | D1: Component | E1: Type | F1: Unit | G1: Forecast qty
C2: Shaker Final Food Recipes | D2: Shawarma Bread OSF | E2: PREP | F2: Each | G2: 293789
C3: T.Final Food Recipe | D3: Tabel Bread | E3: RAW | F3: Each | G3: 208463.85
C4: BBT Final Food Recipe | D4: Kids Fries Sleeves BBT Food Board 250gsm | E4: RAW | F4: Each | G4: 172724
C5: BBT Final Food Recipe | D5: Marinated BBT Chicken tender (PA) | E5: PA | F5: Each | G5: 169049
C6: BBT Final Food Recipe | D6: Wrapping Sheet BBT 30 X 30 | E6: RAW | F6: Each | G6: 132630
C7: Yelo Pizza Finished Product | D7: Hoagie Bread | E7: PREP | F7: Each | G7: 120901
C8: MM-Final Food Recipe | D8: Mishmash Mauve Printed Sheet (25*35) Small Size | E8: RAW | F8: Each | G8: 115928
C9: BBT Final Food Recipe | D9: Fillaaa on Toast | E9: PREP | F9: Each | G9: 111577
C10: T.Final Food Recipe | D10: 2 Oz Clear Souffle Cup W/Lid | E10: RAW | F10: Each | G10: 110232
C11: Shaker Final Food Recipes | D11: S/W Jacket 4x7x28cm Chicken - Shakir | E11: RAW | F11: Each | G11: 101378
C12: Shaker Final Food Recipes | D12: Sandwich Jacket 4x7x28cm - Beef shakir | E12: RAW | F12: Each | G12: 101117
C13: BBT Final Food Recipe | D13: Combo Box BBT Currugated KBC225565 | E13: RAW | F13: Each | G13: 99699
... C2547: BBT Final Food Recipe | D2547: Onion Slab BBT (PA) | E2547: PA | F2547: Kilogram | G2547: -13.668

Sheet SPS
A1: Code | B1: ITEM DESCRIPTION | C1: BASE UNIT | D1: IS ACTIVE | E1: Designation | F1: SubCAT | G1: Current WHS ID | H1: ITEM GROUP | I1: STORAGE TYPE | J1: PURCH UNIT | K1: CURRENT STOCK WAC | L1: TOTAL WAC MTD | M1: LEAD TIME | N1: open delivery note | O1: TRF OUT Delivered & Declined | P1: CURRENT STOCK | Q1: Actual SOH | R1: Last PP | S1: Last PD | T1: Last TR | U1: 46113 | V1: 46143 | W1: 46174 | X1: 46204 | Y1: MIN | Z1: MAX | AA1: AVG TRANSFER OUT | AB1: WEIGHT MIN | AC1: WEIGHT MAX | AD1: DAYS TO LAST (DTL) | AE1: ReqDate | AF1: ReceinvgDate | AG1: OOS DATE | AH1: CURRENT MONTH - MTD TRANSFER | AI1: MTD XTRAPOL % vs. AVG TRANSFER | AJ1: MTD DAYS TO LAST | AK1: MTD OOS | AL1: Target Cover | AM1: SS | AN1: MinOOS DTL | AO1: QTY MTD | AP1: Delivery Freq | AQ1: PIPELINE PENDNG PO | AR1: last Supplier Name | AS1: Status | AT1: Sep-26 FRCst QTY
A2: 103700129 | B2: Turmeric Powder | C2: Kilogram | D2: Active | E2: CPU, Staff Meal, ERMG CK, FM | F2: Spices & Nuts | G2: MAIN WAREHOUSE (FDC) | H2: H/C -Powder | I2: DRY-FOOD | J2: Kilogram | K2: 1.35 | L2: -2.7 | M2: 3 | N2: 0 | O2: 0 | P2: -2 | Q2: -2 | R2: 1.35 | S2: 46251 | T2: 46263 | U2: 7 | V2: 10 | W2: 2 | X2: 6 | Y2: 2 | Z2: 10 | AA2: 6.25 | AB2: 0.32 | AC2: 1.6 | AD2: -6 | AE2: 46242 | AF2: 46250 | AG2: 46257 | AH2: 15 | AI2: 1.5517241 | AJ2: -3 | AK2: 46260 | AL2: 30 | AM2: 15 | AN2: -6 | AO2: 15.517241 | AP2: 1 | AQ2: No QTY | AR2: NO Supplier | AT2: =_xlfn.XLOOKUP(B2,'SWiSH Demand Forecast Sep-26'!D:D,'SWiSH Demand Forecast Sep-26'!G:G,"Not Exist") -> 0.71001
A3: 101200063 | B3: Cottage Cheese Light | C3: Kilogram | D3: Active | E3: Swish Bakery | F3: FRESH | G3: Al MANSOUR WAREHOUSE (PNFDC) | H3: Cheese | I3: CHILLED FOOD | J3: Kilogram | K3: 5.5128968 | L3: 2.7564484 | M3: 3 | N3: 0 | O3: 0 | P3: 0.5 | Q3: 0.5 | R3: 0.95 | S3: 46261 | T3: 46261 | U3: 0 | V3: 193.325 | W3: 69.74 | X3: 83.48 | Y3: 0 | Z3: 193.325 | AA3: 86.63625 | AB3: 0 | AC3: 2.2314562 | AD3: 0 | AE3: 46248 | AF3: 46256 | AG3: 46263 | AH3: 163.58 | AI3: 0.87531716 | AJ3: 0 | AK3: 46263 | AL3: 30 | AM3: 15 | AN3: 0 | AO3: 169.22069 | AP3: 1 | AQ3: 500 | AR3: Petra Food Manufacturing Co , Kuwait Dairy Company KDCow | AT3: =_xlfn.XLOOKUP(B3,'SWiSH Demand Forecast Sep-26'!D:D,'SWiSH Demand Forecast Sep-26'!G:G,"Not Exist") -> Not Exist
A4: 104200028 | B4: Garbage Bag Clear 90X120 | C4: Kilogram | D4: To Be Deactivated | E4: MM, Tabel | F4: CON | G4: Warehouse Common Al Mansour | H4: Kit/Consumable | I4: DRY-NON FOOD | J4: #N/A | K4: 0.7 | L4: 0 | M4: 3 | N4: 0 | O4: 0 | P4: 0 | Q4: 0 | R4: 0 | S4: 43647 | T4: 46231 | U4: 20 | V4: 0 | W4: 0 | X4: 0 | Y4: 0 | Z4: 20 | AA4: 5 | AB4: 0 | AC4: 4 | AD4: 0 | AE4: 46248 | AF4: 46256 | AG4: 46263 | AH4: 0 | AI4: 0 | AL4: NoNeed | AM4: NoNeed | AN4: 0 | AP4: NoNeed | AQ4: No QTY | AR4: NO Supplier | AT4: =_xlfn.XLOOKUP(B4,'SWiSH Demand Forecast Sep-26'!D:D,'SWiSH Demand Forecast Sep-26'!G:G,"Not Exist") -> Not Exist
A5: 100900064 | B5: Mountain Dew Can 150 ML | C5: Each | D5: To Be Deactivated | E5: BBT | F5: BEV | G5: MAIN WAREHOUSE (FDC) | H5: Carbonated Cans | I5: DRY-FOOD | J5: CTN 30 PCS | K5: 0.06606067 | L5: 0 | M5: 3 | N5: 0 | O5: 0 | P5: 0 | Q5: 0 | R5: 1.98182 | S5: 46207 | T5: 46251 | U5: 300 | V5: 420 | W5: 540 | X5: 660 | Y5: 300 | Z5: 660 | AA5: 480 | AB5: 0.625 | AC5: 1.375 | AD5: 0 | AE5: 46248 | AF5: 46256 | AG5: 46263 | AH5: 240 | AI5: 0.37617555 | AJ5: 0 | AK5: 46263 | AL5: NoNeed | AM5: NoNeed | AN5: 0 | AP5: NoNeed | AQ5: No QTY | AR5: NO Supplier | AT5: =_xlfn.XLOOKUP(B5,'SWiSH Demand Forecast Sep-26'!D:D,'SWiSH Demand Forecast Sep-26'!G:G,"Not Exist") -> Not Exist
A6: 104200075 | B6: Tissue Toilet Roll | C6: Each | D6: To Be Deactivated | E6: HO | F6: CLN | G6: Warehouse Common Al Mansour | H6: Kit/Consumable | I6: DRY-NON FOOD | J6: #N/A | K6: 0.41666667 | L6: 0 | M6: 3 | N6: 0 | O6: 0 | P6: 0 | Q6: 0 | R6: 0 | S6: 43647 | T6: 46238 | U6: 48 | V6: 0 | W6: 48 | X6: 0 | Y6: 0 | Z6: 48 | AA6: 24 | AB6: 0 | AC6: 2 | AD6: 0 | AE6: 46248 | AF6: 46256 | AG6: 46263 | AH6: 48 | AI6: 1.0344828 | AJ6: 0 | AK6: 46263 | AL6: NoNeed | AM6: NoNeed | AN6: 0 | AP6: NoNeed | AQ6: No QTY | AR6: NO Supplier | AT6: =_xlfn.XLOOKUP(B6,'SWiSH Demand Forecast Sep-26'!D:D,'SWiSH Demand Forecast Sep-26'!G:G,"Not Exist") -> Not Exist
A7: 101500008 | B7: Dust Pan With Brush Small | C7: Each | D7: To Be Deactivated | E7: Tabel, CPU, MM, ERMG CK | F7: CON | G7: Warehouse Common Al Mansour | H7: Cleaning Tools | I7: DRY-NON FOOD | J7: Each | K7: 0.45 | L7: 0 | M7: 3 | N7: 0 | O7: 0 | P7: 0 | Q7: 0 | R7: 0.45 | S7: 45941 | T7: 46201 | U7: 0 | V7: 0 | W7: 1 | X7: 0 | Y7: 0 | Z7: 1 | AA7: 0.25 | AB7: 0 | AC7: 4 | AD7: 0 | AE7: 46248 | AF7: 46256 | AG7: 46263 | AH7: 0 | AI7: 0 | AL7: NoNeed | AM7: NoNeed | AN7: 0 | AP7: NoNeed | AQ7: No QTY | AR7: NO Supplier | AT7: =_xlfn.XLOOKUP(B7,'SWiSH Demand Forecast Sep-26'!D:D,'SWiSH Demand Forecast Sep-26'!G:G,"Not Exist") -> Not Exist
A8: 106700059 | B8: Highlightner Yellow | C8: Each | D8: To Be Deactivated | E8: BBT, PP, Yelo, Slice, Just C , CPU, Shakir | F8: STA | G8: Al MANSOUR WAREHOUSE (PNFDC) | H8: Stationary | I8: DRY-NON FOOD | J8: Each | K8: 0.17733586 | L8: 0 | M8: 3 | N8: 0 | O8: 0 | P8: 0 | Q8: 0 | R8: 1.875 | S8: 46085 | T8: 46130 | U8: 29 | V8: 0 | W8: 0 | X8: 0 | Y8: 0 | Z8: 29 | AA8: 7.25 | AB8: 0 | AC8: 4 | AD8: 0 | AE8: 46248 | AF8: 46256 | AG8: 46263 | AH8: 0 | AI8: 0 | AL8: NoNeed | AM8: NoNeed | AN8: 0 | AP8: NoNeed | AQ8: No QTY | AR8: NO Supplier | AT8: =_xlfn.XLOOKUP(B8,'SWiSH Demand Forecast Sep-26'!D:D,'SWiSH Demand Forecast Sep-26'!G:G,"Not Exist") -> Not Exist
A9: 104200005 | B9: Aluminum Foil 45 Cm | C9: Each | D9: To Be Deactivated | E9: FM, CPU, Staff Meal, Chili | F9: CON | G9: MAIN WAREHOUSE (FDC) | H9: Kit/Consumable | I9: DRY-NON FOOD | J9: Each | K9: 1.06667 | L9: 0 | M9: 3 | N9: 0 | O9: 0 | P9: 0 | Q9: 0 | R9: 1.06667 | S9: 46212 | T9: 46213 | U9: 3 | V9: 45 | W9: 7 | X9: 46 | Y9: 3 | Z9: 46 | AA9: 25.25 | AB9: 0.11881188 | AC9: 1.8217822 | AD9: 0 | AE9: 46248 | AF9: 46256 | AG9: 46263 | AH9: 0 | AI9: 0 | AL9: NoNeed | AM9: NoNeed | AN9: 0 | AP9: NoNeed | AQ9: No QTY | AR9: NO Supplier | AT9: =_xlfn.XLOOKUP(B9,'SWiSH Demand Forecast Sep-26'!D:D,'SWiSH Demand Forecast Sep-26'!G:G,"Not Exist") -> Not Exist
A10: 107200129 | B10: T-Shirt Polo H/S Purple - Mishmash | C10: Each | D10: Active | E10: MM | F10: UNI | G10: Al MANSOUR WAREHOUSE (PNFDC) | H10: Uniform | I10: DRY-NON FOOD | J10: Each | K10: 2.75 | L10: 0 | M10: 7 | N10: 0 | O10: 0 | P10: 0 | Q10: 0 | R10: 2.75 | S10: 46145 | T10: 46184 | U10: 0 | V10: 49 | W10: 0 | X10: 0 | Y10: 0 | Z10: 49 | AA10: 12.25 | AB10: 0 | AC10: 4 | AD10: 0 | AE10: 46248 | AF10: 46256 | AG10: 46263 | AH10: 0 | AI10: 0 | AL10: OnDemand | AM10: OnDemand | AN10: 0 | AP10: OnDemand | AQ10: No QTY | AR10: NO Supplier | AT10: =_xlfn.XLOOKUP(B10,'SWiSH Demand Forecast Sep-26'!D:D,'SWiSH Demand Forecast Sep-26'!G:G,"Not Exist") -> Not Exist
A11: 100900059 | B11: Lemon Ice Tea Zero Sugar | C11: Each | D11: To Be Deactivated | E11: BBT, Slice, Chili, Shakir, pp, Just C | F11: BEV | G11: MAIN WAREHOUSE (FDC) | H11: Carbonated Cans | I11: DRY-FOOD | J11: Each | K11: 0.11844441 | L11: 0 | M11: 3 | N11: 0 | O11: 0 | P11: 0 | Q11: 0 | R11: 2.73333 | S11: 46214 | T11: 46258 | U11: 198 | V11: 72 | W11: 96 | X11: 936 | Y11: 72 | Z11: 936 | AA11: 325.5 | AB11: 0.22119816 | AC11: 2.875576 | AD11: 0 | AE11: 46248 | AF11: 46256 | AG11: 46263 | AH11: 0 | AI11: 0 | AL11: NoNeed | AM11: NoNeed | AN11: 0 | AP11: NoNeed | AQ11: No QTY | AR11: NO Supplier | AT11: =_xlfn.XLOOKUP(B11,'SWiSH Demand Forecast Sep-26'!D:D,'SWiSH Demand Forecast Sep-26'!G:G,"Not Exist") -> 94
A12: 107200159 | B12: T-Shirt Round Neck JustC | C12: Each | D12: Active | E12: BBT, Just C | F12: UNI | G12: Al MANSOUR WAREHOUSE (PNFDC) | H12: Uniform | I12: DRY-NON FOOD | J12: Each | K12: 1.75 | L12: 0 | M12: 15 | N12: 0 | O12: 0 | P12: 0 | Q12: 0 | R12: 1.75 | S12: 46127 | T12: 46145 | U12: 8 | V12: 10 | W12: 0 | X12: 0 | Y12: 0 | Z12: 10 | AA12: 4.5 | AB12: 0 | AC12: 2.2222222 | AD12: 0 | AE12: 46248 | AF12: 46256 | AG12: 46263 | AH12: 0 | AI12: 0 | AL12: OnDemand | AM12: OnDemand | AN12: 0 | AP12: OnDemand | AQ12: No QTY | AR12: NO Supplier | AT12: =_xlfn.XLOOKUP(B12,'SWiSH Demand Forecast Sep-26'!D:D,'SWiSH Demand Forecast Sep-26'!G:G,"Not Exist") -> Not Exist
A13: 106800335 | B13: Sticker Sealing Foam Box Shakir 3*6 CM | C13: Each | D13: To Be Deactivated | E13: Shakir | F13: PAK | G13: Al MANSOUR WAREHOUSE (PNFDC) | H13: Sticker | I13: DRY-NON FOOD | J13: Each | K13: 0.00444 | L13: 0 | M13: 7 | N13: 0 | O13: 0 | P13: 0 | Q13: 0 | R13: 0.00444 | S13: 46149 | T13: 46203 | U13: 30500 | V13: 10000 | W13: 0 | X13: 0 | Y13: 0 | Z13: 30500 | AA13: 10125 | AB13: 0 | AC13: 3.0123457 | AD13: 0 | AE13: 46248 | AF13: 46256 | AG13: 46263 | AH13: 0 | AI13: 0 | AL13: OnDemand | AM13: OnDemand | AN13: 0 | AP13: OnDemand | AQ13: No QTY | AR13: NO Supplier | AS13: New | AT13: =_xlfn.XLOOKUP(B13,'SWiSH Demand Forecast Sep-26'!D:D,'SWiSH Demand Forecast Sep-26'!G:G,"Not Exist") -> Not Exist
A14: 107200148 | B14: T-Shirt RN RED EMB HS Shakir Back of the house | C14: Each | D14: Active | E14: Shakir | F14: UNI | G14: Al MANSOUR WAREHOUSE (PNFDC) | H14: Uniform | I14: DRY-NON FOOD | J14: Each | K14: 2.5 | L14: 0 | M14: 7 | N14: 0 | O14: 0 | P14: 0 | Q14: 0 | R14: 2.5 | S14: 46151 | T14: 46219 | U14: 8 | V14: 140 | W14: 0 | X14: 0 | Y14: 0 | Z14: 140 | AA14: 37 | AC14: 3.7837838 | AD14: 0 | AE14: 46248 | AF14: 46256 | AG14: 46263 | AH14: 0 | AI14: 0 | AL14: OnDemand | AM14: OnDemand | AN14: 0 | AP14: OnDemand | AQ14: No QTY | AR14: NO Supplier | AS14: New | AT14: =_xlfn.XLOOKUP(B14,'SWiSH Demand Forecast Sep-26'!D:D,'SWiSH Demand Forecast Sep-26'!G:G,"Not Exist") -> Not Exist
A15: 107200102 | B15: Red Baggy Pants For Shakir Back of the house | C15: Each | D15: Active | E15: Shakir | F15: UNI | G15: Al MANSOUR WAREHOUSE (PNFDC) | H15: Uniform | I15: DRY-NON FOOD | J15: Each | K15: 4.5 | L15: 0 | M15: 7 | N15: 0 | O15: 0 | P15: 0 | Q15: 0 | R15: 4.5 | S15: 46151 | T15: 46207 | U15: 0 | V15: 82 | W15: 0 | X15: 0 | Y15: 0 | Z15: 82 | AA15: 20.5 | AB15: 0 | AC15: 4 | AD15: 0 | AE15: 46248 | AF15: 46256 | AG15: 46263 | AH15: 0 | AI15: 0 | AL15: OnDemand | AM15: OnDemand | AN15: 0 | AP15: OnDemand | AQ15: No QTY | AR15: NO Supplier | AS15: New | AT15: =_xlfn.XLOOKUP(B15,'SWiSH Demand Forecast Sep-26'!D:D,'SWiSH Demand Forecast Sep-26'!G:G,"Not Exist") -> Not Exist
A16: 106200080 | B16: SWiSH Mayonnaise | C16: Liter | D16: Active | E16: Just C , CPU, BBT, ERMG CK, LB, R&D | F16: Oils & Sauces | G16: MAIN WAREHOUSE (FDC) | H16: Sauce | I16: DRY-FOOD | J16: CTN 4 Galon 3.78 Liter | K16: 0.89137369 | L16: 0 | M16: 3 | N16: 0 | O16: 0 | P16: 0 | Q16: 0 | R16: 13.5 | S16: 46124 | T16: 46203 | U16: 16794.54 | V16: 0 | W16: 0 | X16: 0 | Y16: 0 | Z16: 16794.54 | AA16: 4198.635 | AB16: 0 | AC16: 4 | AD16: 0 | AE16: 46248 | AF16: 46256 | AG16: 46263 | AH16: 0 | AI16: 0 | AL16: 5 | AM16: 3 | AN16: 0 | AO16: 0 | AP16: 8 | AQ16: No QTY | AR16: NO Supplier | AT16: =_xlfn.XLOOKUP(B16,'SWiSH Demand Forecast Sep-26'!D:D,'SWiSH Demand Forecast Sep-26'!G:G,"Not Exist") -> Not Exist
A17: 107200110 | B17: Shirt white Full Sleeve Shakir | C17: Each | D17: Non-Moving | E17: Shakir | F17: UNI | G17: Al MANSOUR WAREHOUSE (PNFDC) | H17: Uniform | I17: DRY-NON FOOD | J17: Each | K17: 4 | L17: 0 | M17: 15 | N17: 0 | O17: 0 | P17: 0 | Q17: 0 | R17: 4 | S17: 45915 | T17: 46127 | U17: 16 | V17: 0 | W17: 0 | X17: 0 | Y17: 0 | Z17: 16 | AA17: 4 | AB17: 0 | AC17: 4 | AD17: 0 | AE17: 46248 | AF17: 46256 | AG17: 46263 | AH17: 0 | AI17: 0 | AL17: OnDemand | AM17: OnDemand | AN17: 0 | AP17: OnDemand | AQ17: No QTY | AR17: NO Supplier | AT17: =_xlfn.XLOOKUP(B17,'SWiSH Demand Forecast Sep-26'!D:D,'SWiSH Demand Forecast Sep-26'!G:G,"Not Exist") -> Not Exist
A18: 105600033 | B18: Bag Vacuum 20x30 Cm ERMG | C18: Kilogram | D18: Non-Moving | E18: CPU, ERMG CK | F18: CON | G18: Warehouse ERMG-Mishmash | H18: Plastic Bags | I18: DRY-NON FOOD | J18: Kilogram | K18: 0.7 | L18: 0 | M18: 30 | N18: 0 | O18: 0 | P18: 0 | Q18: 0 | R18: 0.65 | S18: 46133 | T18: 46140 | U18: 300 | V18: 0 | W18: 0 | X18: 0 | Y18: 0 | Z18: 300 | AA18: 75 | AB18: 0 | AC18: 4 | AD18: 0 | AE18: 46248 | AF18: 46256 | AG18: 46263 | AH18: 0 | AI18: 0 | AL18: OnDemand | AM18: OnDemand | AN18: 0 | AP18: OnDemand | AQ18: No QTY | AR18: NO Supplier | AT18: =_xlfn.XLOOKUP(B18,'SWiSH Demand Forecast Sep-26'!D:D,'SWiSH Demand Forecast Sep-26'!G:G,"Not Exist") -> Not Exist
A19: 107200123 | B19: T-Shirt POLO Half Sleeve Black JustC | C19: Each | D19: Non-Moving | E19: BBT, Just C | F19: UNI | G19: Warehouse Ardiya | H19: Uniform | I19: DRY-NON FOOD | J19: Each | K19: 2.5 | L19: 0 | M19: 15 | N19: 0 | O19: 0 | P19: 0 | Q19: 0 | R19: 2.5 | S19: 46127 | T19: 46136 | U19: 8 | V19: 0 | W19: 0 | X19: 0 | Y19: 0 | Z19: 8 | AA19: 2 | AB19: 0 | AC19: 4 | AD19: 0 | AE19: 46248 | AF19: 46256 | AG19: 46263 | AH19: 0 | AI19: 0 | AL19: OnDemand | AM19: OnDemand | AN19: 0 | AP19: OnDemand | AQ19: No QTY | AR19: NO Supplier | AT19: =_xlfn.XLOOKUP(B19,'SWiSH Demand Forecast Sep-26'!D:D,'SWiSH Demand Forecast Sep-26'!G:G,"Not Exist") -> Not Exist
A20: 107200128 | B20: T-Shirt Polo H/S Oily Maintenance Swish | C20: Each | D20: Non-Moving | E20: Stores office | F20: UNI | G20: Warehouse Common Al Mansour | H20: Uniform | I20: DRY-NON FOOD | J20: Each | K20: 3.25 | L20: 0 | M20: 7 | N20: 0 | O20: 0 | P20: 0 | Q20: 0 | R20: 3.25 | S20: 46127 | T20: 46137 | U20: 3 | V20: 0 | W20: 0 | X20: 0 | Y20: 0 | Z20: 3 | AA20: 0.75 | AB20: 0 | AC20: 4 | AD20: 0 | AE20: 46248 | AF20: 46256 | AG20: 46263 | AH20: 0 | AI20: 0 | AL20: OnDemand | AM20: OnDemand | AN20: 0 | AP20: OnDemand | AQ20: No QTY | AR20: NO Supplier | AT20: =_xlfn.XLOOKUP(B20,'SWiSH Demand Forecast Sep-26'!D:D,'SWiSH Demand Forecast Sep-26'!G:G,"Not Exist") -> Not Exist
A21: 104800008 | B21: Voda Voda Glass Bottle 330 Ml | C21: Each | D21: Non-Moving | E21: FM | F21: BEV | G21: Warehouse FM | H21: Mineral Water | I21: DRY-FOOD | J21: Packet 12 pcs | K21: 0.2375 | L21: 0 | M21: 3 | N21: 0 | O21: 0 | P21: 0 | Q21: 0 | R21: 2.85 | S21: 46138 | T21: 46162 | U21: 276 | V21: 204 | W21: 0 | X21: 0 | Y21: 0 | Z21: 276 | AA21: 120 | AB21: 0 | AC21: 2.3 | AD21: 0 | AE21: 46248 | AF21: 46256 | AG21: 46263 | AH21: 0 | AI21: 0 | AL21: OnDemand | AM21: OnDemand | AN21: 0 | AP21: OnDemand | AQ21: No QTY | AR21: NO Supplier | AT21: =_xlfn.XLOOKUP(B21,'SWiSH Demand Forecast Sep-26'!D:D,'SWiSH Demand Forecast Sep-26'!G:G,"Not Exist") -> Not Exist
A22: 106800040 | B22: FM Sticker for Bag Seal 5.1x11cm Matafi | C22: Each | D22: To Be Deactivated | E22: FM | F22: PAK | G22: Warehouse ETC Al Mansour | H22: Sticker | I22: DRY-NON FOOD | J22: Each | K22: 0.003 | L22: 0 | M22: 15 | N22: 0 | O22: 0 | P22: 0 | Q22: 0 | R22: 0.003 | S22: 45994 | T22: 46199 | U22: 2500 | V22: 0 | W22: 0 | X22: 0 | Y22: 0 | Z22: 2500 | AA22: 625 | AB22: 0 | AC22: 4 | AD22: 0 | AE22: 46248 | AF22: 46256 | AG22: 46263 | AH22: 0 | AI22: 0 | AL22: NoNeed | AM22: NoNeed | AN22: 0 | AP22: NoNeed | AQ22: No QTY | AR22: NO Supplier | AT22: =_xlfn.XLOOKUP(B22,'SWiSH Demand Forecast Sep-26'!D:D,'SWiSH Demand Forecast Sep-26'!G:G,"Not Exist") -> Not Exist
A23: 101400023 | B23: Glass Cleaner | C23: Each | D23: To Be Deactivated | E23: Yelo, Slice, pp, Shakir, CPU, BBT, HO, Chili, Stores office | F23: CLN | G23: Al MANSOUR WAREHOUSE (PNFDC) | H23: Cleaning Material | I23: DRY-NON FOOD | J23: CTN 6 pcs | K23: 1.5833333 | L23: 0 | M23: 3 | N23: 0 | O23: 0 | P23: 0 | Q23: 0 | R23: 9.5 | S23: 46096 | T23: 46235 | U23: 1 | V23: 3 | W23: 0 | X23: 0 | Y23: 0 | Z23: 3 | AA23: 1 | AB23: 0 | AC23: 3 | AD23: 0 | AE23: 46248 | AF23: 46256 | AG23: 46263 | AH23: 0 | AI23: 0 | AL23: OnDemand | AM23: OnDemand | AN23: 0 | AP23: OnDemand | AQ23: No QTY | AR23: NO Supplier | AT23: =_xlfn.XLOOKUP(B23,'SWiSH Demand Forecast Sep-26'!D:D,'SWiSH Demand Forecast Sep-26'!G:G,"Not Exist") -> Not Exist
A24: 101400049 | B24: Oven Cleaner Suma D 96 | C24: Liter | D24: To Be Deactivated | E24: FM, Shakir, pp, CPU, Yelo, BBT, Slice, Chili | F24: CLN | G24: MAIN WAREHOUSE (FDC) | H24: Cleaning Material | I24: DRY-NON FOOD | J24: CTN 2 Galon 5 Liter | K24: 1.75 | L24: 0 | M24: 3 | N24: 0 | O24: 0 | P24: 0 | Q24: 0 | R24: 14 | S24: 46175 | T24: 46252 | U24: 1510 | V24: 1585 | W24: 105 | X24: 0 | Y24: 0 | Z24: 1585 | AA24: 800 | AB24: 0 | AC24: 1.98125 | AD24: 0 | AE24: 46248 | AF24: 46256 | AG24: 46263 | AH24: 0 | AI24: 0 | AL24: NoNeed | AM24: NoNeed | AN24: 0 | AP24: NoNeed | AQ24: No QTY | AR24: NO Supplier | AT24: =_xlfn.XLOOKUP(B24,'SWiSH Demand Forecast Sep-26'!D:D,'SWiSH Demand Forecast Sep-26'!G:G,"Not Exist") -> Not Exist
A25: 106800054 | B25: FM Stk Frzn Sambosa Cheese Jalp Back 12*12 | C25: Each | D25: Slow-Moving | E25: FM | F25: PAK | G25: MAIN WAREHOUSE (FDC) | H25: Sticker | I25: DRY-NON FOOD | J25: Each | K25: 0.05 | L25: 0 | M25: 7 | N25: 0 | O25: 0 | P25: 0 | Q25: 0 | R25: 0.05 | S25: 46088 | T25: 46111 | U25: 1000 | V25: 0 | W25: 0 | X25: 0 | Y25: 0 | Z25: 1000 | AA25: 250 | AB25: 0 | AC25: 4 | AD25: 0 | AE25: 46248 | AF25: 46256 | AG25: 46263 | AH25: 0 | AI25: 0 | AL25: OnDemand | AM25: OnDemand | AN25: 0 | AP25: OnDemand | AQ25: No QTY | AR25: NO Supplier | AT25: =_xlfn.XLOOKUP(B25,'SWiSH Demand Forecast Sep-26'!D:D,'SWiSH Demand Forecast Sep-26'!G:G,"Not Exist") -> Not Exist
A26: 107200035 | B26: Chef Coat - Tabel | C26: Each | D26: Active | E26: Tabel | F26: UNI | G26: Al MANSOUR WAREHOUSE (PNFDC) | H26: Uniform | I26: DRY-NON FOOD | J26: Each | K26: 6 | L26: 0 | M26: 15 | N26: 0 | O26: 0 | P26: 0 | Q26: 0 | R26: 6 | S26: 46222 | T26: 46225 | U26: 0 | V26: 0 | W26: 30 | X26: 12 | Y26: 0 | Z26: 30 | AA26: 10.5 | AB26: 0 | AC26: 2.8571429 | AD26: 0 | AE26: 46248 | AF26: 46256 | AG26: 46263 | AH26: 0 | AI26: 0 | AL26: OnDemand | AM26: OnDemand | AN26: 0 | AP26: OnDemand | AQ26: 16 | AR26: Design Stores | AT26: =_xlfn.XLOOKUP(B26,'SWiSH Demand Forecast Sep-26'!D:D,'SWiSH Demand Forecast Sep-26'!G:G,"Not Exist") -> Not Exist
A27: 107200020 | B27: BBT Steward Black Pants | C27: Each | D27: Non-Moving | E27: BBT | F27: UNI | G27: Warehouse Non Moving items | H27: Uniform | I27: DRY-NON FOOD | J27: Each | K27: 4.75 | L27: 0 | M27: 15 | N27: 0 | O27: 0 | P27: 0 | Q27: 0 | R27: 4.75 | S27: 46186 | T27: 46187 | U27: 9 | V27: 0 | W27: 3 | X27: 0 | Y27: 0 | Z27: 9 | AA27: 3 | AB27: 0 | AC27: 3 | AD27: 0 | AE27: 46248 | AF27: 46256 | AG27: 46263 | AH27: 0 | AI27: 0 | AL27: OnDemand | AM27: OnDemand | AN27: 0 | AP27: OnDemand | AQ27: No QTY | AR27: NO Supplier | AT27: =_xlfn.XLOOKUP(B27,'SWiSH Demand Forecast Sep-26'!D:D,'SWiSH Demand Forecast Sep-26'!G:G,"Not Exist") -> Not Exist
A28: 105600029 | B28: Bag Plastic White HD - Shakir 70h*45w | C28: Kilogram | D28: To Be Deactivated | E28: Shakir | F28: PAK | G28: Al MANSOUR WAREHOUSE (PNFDC) | H28: Plastic Bags | I28: DRY-NON FOOD | J28: Kilogram | K28: 0.45003592 | L28: 0 | M28: 30 | N28: 0 | O28: 0 | P28: 0 | Q28: 0 | R28: 0.45 | S28: 46095 | T28: 46195 | U28: 220 | V28: 480 | W28: 100 | X28: 0 | Y28: 0 | Z28: 480 | AA28: 200 | AB28: 0 | AC28: 2.4 | AD28: 0 | AE28: 46248 | AF28: 46256 | AG28: 46263 | AH28: 0 | AI28: 0 | AL28: NoNeed | AM28: NoNeed | AN28: 0 | AP28: NoNeed | AQ28: No QTY | AR28: NO Supplier | AT28: =_xlfn.XLOOKUP(B28,'SWiSH Demand Forecast Sep-26'!D:D,'SWiSH Demand Forecast Sep-26'!G:G,"Not Exist") -> Not Exist
A29: 107200127 | B29: T-Shirt Polo H/S Grey -Swish | C29: Each | D29: Non-Moving | E29: HO, Stores office | F29: UNI | G29: Warehouse Common Al Mansour | H29: Uniform | I29: DRY-NON FOOD | J29: Each | K29: 3.25 | L29: 0 | M29: 15 | N29: 0 | O29: 0 | P29: 0 | Q29: 0 | R29: 3.25 | S29: 46261 | T29: 46261 | U29: 6 | V29: 0 | W29: 0 | X29: 9 | Y29: 0 | Z29: 9 | AA29: 3.75 | AB29: 0 | AC29: 2.4 | AD29: 0 | AE29: 46248 | AF29: 46256 | AG29: 46263 | AH29: 6 | AI29: 0.68965517 | AJ29: 0 | AK29: 46263 | AL29: OnDemand | AM29: OnDemand | AN29: 0 | AP29: OnDemand | AQ29: No QTY | AR29: NO Supplier | AT29: =_xlfn.XLOOKUP(B29,'SWiSH Demand Forecast Sep-26'!D:D,'SWiSH Demand Forecast Sep-26'!G:G,"Not Exist") -> Not Exist
A30: 107200154 | B30: T-Shirt Round Neck Black F/S - BBT Plain | C30: Each | D30: Non-Moving | E30: BBT | F30: UNI | G30: Warehouse ETC Al Mansour | H30: Uniform | I30: DRY-NON FOOD | J30: Each | K30: 3.25 | L30: 0 | M30: 7 | N30: 0 | O30: 0 | P30: 0 | Q30: 0 | R30: 3.25 | S30: 46127 | T30: 46135 | U30: 9 | V30: 0 | W30: 0 | X30: 0 | Y30: 0 | Z30: 9 | AA30: 2.25 | AB30: 0 | AC30: 4 | AD30: 0 | AE30: 46248 | AF30: 46256 | AG30: 46263 | AH30: 0 | AI30: 0 | AL30: OnDemand | AM30: OnDemand | AN30: 0 | AP30: OnDemand | AQ30: No QTY | AR30: NO Supplier | AS30: New | AT30: =_xlfn.XLOOKUP(B30,'SWiSH Demand Forecast Sep-26'!D:D,'SWiSH Demand Forecast Sep-26'!G:G,"Not Exist") -> Not Exist
A31: 107200184 | B31: White Shirt EMB Shakir-Managers | C31: Each | D31: Active | E31: Shakir | F31: UNI | G31: Al MANSOUR WAREHOUSE (PNFDC) | H31: Uniform | I31: DRY-NON FOOD | J31: Each | K31: 4.25 | L31: 0 | M31: 7 | N31: 0 | O31: 0 | P31: 0 | Q31: 0 | R31: 4.25 | S31: 46092 | T31: 46117 | U31: 12 | V31: 0 | W31: 0 | X31: 0 | Y31: 0 | Z31: 12 | AA31: 3 | AB31: 0 | AC31: 4 | AD31: 0 | AE31: 46248 | AF31: 46256 | AG31: 46263 | AH31: 0 | AI31: 0 | AL31: OnDemand | AM31: OnDemand | AN31: 0 | AP31: OnDemand | AQ31: No QTY | AR31: NO Supplier | AS31: New | AT31: =_xlfn.XLOOKUP(B31,'SWiSH Demand Forecast Sep-26'!D:D,'SWiSH Demand Forecast Sep-26'!G:G,"Not Exist") -> Not Exist
A32: 106800052 | B32: FM Stk Frzn Sambosa CHKN Musakan Back 12*12 | C32: Each | D32: Slow-Moving | E32: FM | F32: PAK | G32: MAIN WAREHOUSE (FDC) | H32: Sticker | I32: DRY-NON FOOD | J32: Each | K32: 0.05 | L32: 0 | M32: 7 | N32: 0 | O32: 0 | P32: 0 | Q32: 0 | R32: 0.05 | S32: 46088 | T32: 46111 | U32: 1000 | V32: 0 | W32: 0 | X32: 0 | Y32: 0 | Z32: 1000 | AA32: 250 | AB32: 0 | AC32: 4 | AD32: 0 | AE32: 46248 | AF32: 46256 | AG32: 46263 | AH32: 0 | AI32: 0 | AL32: OnDemand | AM32: OnDemand | AN32: 0 | AP32: OnDemand | AQ32: No QTY | AR32: NO Supplier | AT32: =_xlfn.XLOOKUP(B32,'SWiSH Demand Forecast Sep-26'!D:D,'SWiSH Demand Forecast Sep-26'!G:G,"Not Exist") -> Not Exist
A33: 107200072 | B33: Jeans | C33: Each | D33: Active | E33: Stores office | F33: UNI | G33: Al MANSOUR WAREHOUSE (PNFDC) | H33: Uniform | I33: DRY-NON FOOD | J33: Each | K33: 4 | L33: 0 | M33: 15 | N33: 0 | O33: 0 | P33: 0 | Q33: 0 | R33: 4 | S33: 46127 | T33: 46175 | U33: 2 | V33: 0 | W33: 0 | X33: 0 | Y33: 0 | Z33: 2 | AA33: 0.5 | AB33: 0 | AC33: 4 | AD33: 0 | AE33: 46248 | AF33: 46256 | AG33: 46263 | AH33: 0 | AI33: 0 | AL33: OnDemand | AM33: OnDemand | AN33: 0 | AP33: OnDemand | AQ33: No QTY | AR33: NO Supplier | AT33: =_xlfn.XLOOKUP(B33,'SWiSH Demand Forecast Sep-26'!D:D,'SWiSH Demand Forecast Sep-26'!G:G,"Not Exist") -> Not Exist
A34: 106800056 | B34: FM Stk Frzn Sambosa Seasoned Beef Back 12*12 | C34: Each | D34: Slow-Moving | E34: FM | F34: PAK | G34: MAIN WAREHOUSE (FDC) | H34: Sticker | I34: DRY-NON FOOD | J34: Each | K34: 0.05 | L34: 0 | M34: 7 | N34: 0 | O34: 0 | P34: 0 | Q34: 0 | R34: 0.05 | S34: 46088 | T34: 46111 | U34: 1000 | V34: 0 | W34: 0 | X34: 0 | Y34: 0 | Z34: 1000 | AA34: 250 | AB34: 0 | AC34: 4 | AD34: 0 | AE34: 46248 | AF34: 46256 | AG34: 46263 | AH34: 0 | AI34: 0 | AL34: OnDemand | AM34: OnDemand | AN34: 0 | AP34: OnDemand | AQ34: No QTY | AR34: NO Supplier | AT34: =_xlfn.XLOOKUP(B34,'SWiSH Demand Forecast Sep-26'!D:D,'SWiSH Demand Forecast Sep-26'!G:G,"Not Exist") -> Not Exist
A35: 106800055 | B35: FM Stk Frzn Sambosa Cheese Jalp Front 25*15 | C35: Each | D35: Slow-Moving | E35: FM | F35: PAK | G35: MAIN WAREHOUSE (FDC) | H35: Sticker | I35: DRY-NON FOOD | J35: Each | K35: 0.13 | L35: 0 | M35: 7 | N35: 0 | O35: 0 | P35: 0 | Q35: 0 | R35: 0.13 | S35: 46088 | T35: 46111 | U35: 1000 | V35: 0 | W35: 0 | X35: 0 | Y35: 0 | Z35: 1000 | AA35: 250 | AB35: 0 | AC35: 4 | AD35: 0 | AE35: 46248 | AF35: 46256 | AG35: 46263 | AH35: 0 | AI35: 0 | AL35: OnDemand | AM35: OnDemand | AN35: 0 | AP35: OnDemand | AQ35: No QTY | AR35: NO Supplier | AT35: =_xlfn.XLOOKUP(B35,'SWiSH Demand Forecast Sep-26'!D:D,'SWiSH Demand Forecast Sep-26'!G:G,"Not Exist") -> Not Exist
A36: 106800053 | B36: FM Stk Frzn Sambosa CHKN Musakan Front 25*15 | C36: Each | D36: Slow-Moving | E36: FM | F36: PAK | G36: MAIN WAREHOUSE (FDC) | H36: Sticker | I36: DRY-NON FOOD | J36: Each | K36: 0.13 | L36: 0 | M36: 7 | N36: 0 | O36: 0 | P36: 0 | Q36: 0 | R36: 0.13 | S36: 46088 | T36: 46111 | U36: 1000 | V36: 0 | W36: 0 | X36: 0 | Y36: 0 | Z36: 1000 | AA36: 250 | AB36: 0 | AC36: 4 | AD36: 0 | AE36: 46248 | AF36: 46256 | AG36: 46263 | AH36: 0 | AI36: 0 | AL36: OnDemand | AM36: OnDemand | AN36: 0 | AP36: OnDemand | AQ36: No QTY | AR36: NO Supplier | AT36: =_xlfn.XLOOKUP(B36,'SWiSH Demand Forecast Sep-26'!D:D,'SWiSH Demand Forecast Sep-26'!G:G,"Not Exist") -> Not Exist
A37: 106800057 | B37: FM Stk Frzn Sambosa Seasoned Beef Front 25*15 | C37: Each | D37: Slow-Moving | E37: FM | F37: PAK | G37: MAIN WAREHOUSE (FDC) | H37: Sticker | I37: DRY-NON FOOD | J37: Each | K37: 0.13 | L37: 0 | M37: 7 | N37: 0 | O37: 0 | P37: 0 | Q37: 0 | R37: 0.13 | S37: 46088 | T37: 46111 | U37: 1000 | V37: 0 | W37: 0 | X37: 0 | Y37: 0 | Z37: 1000 | AA37: 250 | AB37: 0 | AC37: 4 | AD37: 0 | AE37: 46248 | AF37: 46256 | AG37: 46263 | AH37: 0 | AI37: 0 | AL37: OnDemand | AM37: OnDemand | AN37: 0 | AP37: OnDemand | AQ37: No QTY | AR37: NO Supplier | AT37: =_xlfn.XLOOKUP(B37,'SWiSH Demand Forecast Sep-26'!D:D,'SWiSH Demand Forecast Sep-26'!G:G,"Not Exist") -> Not Exist
A38: 107200093 | B38: Pants Black Shakir - Managers | C38: Each | D38: Active | E38: Shakir | F38: UNI | G38: Al MANSOUR WAREHOUSE (PNFDC) | H38: Uniform | I38: DRY-NON FOOD | J38: Each | K38: 3.75 | L38: 0 | M38: 7 | N38: 0 | O38: 0 | P38: 0 | Q38: 0 | R38: 3.75 | S38: 46078 | T38: 46131 | U38: 6 | V38: 0 | W38: 0 | X38: 0 | Y38: 0 | Z38: 6 | AA38: 1.5 | AB38: 0 | AC38: 4 | AD38: 0 | AE38: 46248 | AF38: 46256 | AG38: 46263 | AH38: 0 | AI38: 0 | AL38: OnDemand | AM38: OnDemand | AN38: 0 | AP38: OnDemand | AQ38: No QTY | AR38: NO Supplier | AS38: New | AT38: =_xlfn.XLOOKUP(B38,'SWiSH Demand Forecast Sep-26'!D:D,'SWiSH Demand Forecast Sep-26'!G:G,"Not Exist") -> Not Exist
A39: 107200111 | B39: Shirt white Half Sleeve Shakir | C39: Each | D39: Active | E39: Shakir | F39: UNI | G39: Al MANSOUR WAREHOUSE (PNFDC) | H39: Uniform | I39: DRY-NON FOOD | J39: Each | K39: 3.75 | L39: 0 | M39: 15 | N39: 0 | O39: 0 | P39: 0 | Q39: 0 | R39: 3.75 | S39: 46025 | T39: 46119 | U39: 9 | V39: 0 | W39: 0 | X39: 0 | Y39: 0 | Z39: 9 | AA39: 2.25 | AB39: 0 | AC39: 4 | AD39: 0 | AE39: 46248 | AF39: 46256 | AG39: 46263 | AH39: 0 | AI39: 0 | AL39: OnDemand | AM39: OnDemand | AN39: 0 | AP39: OnDemand | AQ39: No QTY | AR39: NO Supplier | AT39: =_xlfn.XLOOKUP(B39,'SWiSH Demand Forecast Sep-26'!D:D,'SWiSH Demand Forecast Sep-26'!G:G,"Not Exist") -> Not Exist
A40: 106800336 | B40: Sticker Bag Sealing Shakir & BBT | C40: Each | D40: To Be Deactivated | E40: Shakir, BBT | F40: PAK | G40: Al MANSOUR WAREHOUSE (PNFDC) | H40: Sticker | I40: DRY-NON FOOD | J40: Each | K40: 0.01333 | L40: 0 | M40: 7 | N40: 0 | O40: 0 | P40: 0 | Q40: 0 | R40: 0.01333 | S40: 46119 | T40: 46122 | U40: 1500 | V40: 0 | W40: 0 | X40: 0 | Y40: 0 | Z40: 1500 | AA40: 375 | AB40: 0 | AC40: 4 | AD40: 0 | AE40: 46248 | AF40: 46256 | AG40: 46263 | AH40: 0 | AI40: 0 | AL40: OnDemand | AM40: OnDemand | AN40: 0 | AP40: OnDemand | AQ40: No QTY | AR40: NO Supplier | AS40: New | AT40: =_xlfn.XLOOKUP(B40,'SWiSH Demand Forecast Sep-26'!D:D,'SWiSH Demand Forecast Sep-26'!G:G,"Not Exist") -> Not Exist
...
